[2019-10-10 20:15:02,882] INFO in app.py - framework_error [line:17]: 404 Not Found: The requested URL was not found on the server.  If you entered the URL manually please check your spelling and try again.
[2019-10-10 20:15:03,050] INFO in app.py - framework_error [line:17]: 404 Not Found: The requested URL was not found on the server.  If you entered the URL manually please check your spelling and try again.
[2019-10-10 20:15:17,230] INFO in app.py - framework_error [line:17]: 404 Not Found: The requested URL was not found on the server.  If you entered the URL manually please check your spelling and try again.
[2019-10-10 20:15:17,293] INFO in app.py - framework_error [line:17]: 404 Not Found: The requested URL was not found on the server.  If you entered the URL manually please check your spelling and try again.
[2019-10-10 20:15:27,356] INFO in app.py - framework_error [line:17]: 405 Method Not Allowed: The method is not allowed for the requested URL.
[2019-10-10 20:15:27,449] INFO in app.py - framework_error [line:17]: 404 Not Found: The requested URL was not found on the server.  If you entered the URL manually please check your spelling and try again.
[2019-10-10 20:16:08,671] INFO in app.py - framework_error [line:17]: 405 Method Not Allowed: The method is not allowed for the requested URL.
[2019-10-10 20:16:08,754] INFO in app.py - framework_error [line:17]: 404 Not Found: The requested URL was not found on the server.  If you entered the URL manually please check your spelling and try again.
[2019-10-10 20:16:39,382] INFO in app.py - framework_error [line:17]: 404 Not Found: The requested URL was not found on the server.  If you entered the URL manually please check your spelling and try again.
[2019-10-10 20:24:01,944] INFO in app.py - framework_error [line:17]: 404 Not Found: The requested URL was not found on the server.  If you entered the URL manually please check your spelling and try again.
[2019-10-11 14:22:59,685] INFO in app.py - framework_error [line:17]: [Errno 2] No such file or directory: '../../config/hosts.yaml'
[2019-10-11 14:26:47,016] INFO in app.py - framework_error [line:17]: [Errno 2] No such file or directory: '../config/hosts.yaml'
[2019-10-11 14:27:06,351] INFO in app.py - framework_error [line:17]: [Errno 2] No such file or directory: '../../../config/hosts.yaml'
[2019-10-11 14:27:42,045] INFO in app.py - framework_error [line:17]: [Errno 22] Invalid argument: 'D:\\pythonProgram\\docker-manager\\docker-manager-flask\x07pp\\config\\hosts.yaml'
[2019-10-11 14:29:23,315] INFO in app.py - framework_error [line:17]: [Errno 2] No such file or directory: '../../config/hosts.yaml'
[2019-10-11 14:30:40,659] INFO in app.py - framework_error [line:17]: [Errno 2] No such file or directory: '../../hosts.yaml'
[2019-10-11 14:31:32,215] INFO in app.py - framework_error [line:17]: [Errno 2] No such file or directory: 'hosts.yaml'
[2019-10-11 14:35:42,477] INFO in app.py - framework_error [line:17]: 404 Not Found: The requested URL was not found on the server.  If you entered the URL manually please check your spelling and try again.
[2019-10-11 14:37:11,607] INFO in app.py - framework_error [line:17]: 404 Not Found: The requested URL was not found on the server.  If you entered the URL manually please check your spelling and try again.
[2019-10-11 14:38:07,276] INFO in app.py - framework_error [line:17]: 404 Not Found: The requested URL was not found on the server.  If you entered the URL manually please check your spelling and try again.
[2019-10-11 14:38:49,213] INFO in app.py - framework_error [line:17]: 404 Not Found: The requested URL was not found on the server.  If you entered the URL manually please check your spelling and try again.
[2019-10-11 14:45:10,694] INFO in app.py - framework_error [line:17]: validate_for_api() missing 1 required positional argument: 'self'
[2019-10-11 14:45:43,189] INFO in app.py - framework_error [line:17]: 404 Not Found: The requested URL was not found on the server.  If you entered the URL manually please check your spelling and try again.
[2019-10-11 14:45:56,856] INFO in app.py - framework_error [line:17]: HTTPConnectionPool(host='www.guojiaxing.re', port=2375): Max retries exceeded with url: /v1.35/info (Caused by NewConnectionError('<urllib3.connection.HTTPConnection object at 0x000001A26C234B00>: Failed to establish a new connection: [Errno 11001] getaddrinfo failed',))
[2019-10-11 15:21:22,051] INFO in app.py - framework_error [line:17]: 'dict' object has no attribute 'name'
[2019-10-11 15:21:52,033] INFO in app.py - framework_error [line:17]: 'dict' object has no attribute 'Name'
[2019-10-11 15:22:44,134] INFO in app.py - framework_error [line:17]: 404 Not Found: The requested URL was not found on the server.  If you entered the URL manually please check your spelling and try again.
[2019-10-11 15:44:10,105] INFO in app.py - framework_error [line:17]: 404 Not Found: The requested URL was not found on the server.  If you entered the URL manually please check your spelling and try again.
[2019-10-11 15:45:51,100] INFO in app.py - framework_error [line:17]: 404 Not Found: The requested URL was not found on the server.  If you entered the URL manually please check your spelling and try again.
[2019-10-11 16:03:00,021] INFO in app.py - framework_error [line:17]: 'DockerClient' object has no attribute 'list'
[2019-10-11 16:06:21,046] INFO in app.py - framework_error [line:17]: 500 Internal Server Error: None
[2019-10-11 16:06:33,074] INFO in app.py - framework_error [line:17]: 500 Internal Server Error: None
[2019-10-11 16:08:56,029] INFO in app.py - framework_error [line:17]: 500 Internal Server Error: None
[2019-10-11 16:13:19,975] INFO in app.py - framework_error [line:17]: 500 Internal Server Error: None
[2019-10-11 16:13:20,092] INFO in app.py - framework_error [line:17]: 404 Not Found: The requested URL was not found on the server.  If you entered the URL manually please check your spelling and try again.
[2019-10-11 16:14:28,992] INFO in app.py - framework_error [line:17]: 500 Internal Server Error: None
[2019-10-11 16:14:29,091] INFO in app.py - framework_error [line:17]: 404 Not Found: The requested URL was not found on the server.  If you entered the URL manually please check your spelling and try again.
[2019-10-11 16:15:01,014] INFO in app.py - framework_error [line:17]: 500 Internal Server Error: None
[2019-10-11 16:15:01,118] INFO in app.py - framework_error [line:17]: 404 Not Found: The requested URL was not found on the server.  If you entered the URL manually please check your spelling and try again.
[2019-10-11 16:22:59,163] INFO in app.py - framework_error [line:17]: 500 Internal Server Error: None
[2019-10-11 16:27:51,558] INFO in app.py - framework_error [line:17]: 500 Internal Server Error: None
[2019-10-11 16:31:49,968] INFO in app.py - framework_error [line:17]: 'list' object has no attribute 'RepoTags'
[2019-10-11 16:32:30,968] INFO in app.py - framework_error [line:17]: 'list' object has no attribute 'attrs'
[2019-10-11 16:32:52,047] INFO in app.py - framework_error [line:17]: 'dict' object has no attribute 'RepoTags'
[2019-10-11 17:50:25,960] INFO in app.py - framework_error [line:17]: 'name'
[2019-10-11 17:51:32,987] INFO in app.py - framework_error [line:17]: 'name'
[2019-10-11 17:52:36,542] INFO in app.py - framework_error [line:17]: 'name'
[2019-10-11 17:53:01,908] INFO in app.py - framework_error [line:17]: 'status'
[2019-10-11 17:54:11,301] INFO in app.py - framework_error [line:17]: 'Status'
[2019-10-11 19:43:33,063] INFO in app.py - framework_error [line:17]: 400 Bad Request: {'host': ['不许为空']}
[2019-10-11 22:04:23,978] INFO in app.py - framework_error [line:17]: 400 Bad Request: {'host': ['不许为空']}
[2019-10-11 22:06:07,674] INFO in app.py - framework_error [line:17]: 400 Bad Request: {'host': ['不许为空']}
[2019-10-11 22:07:48,745] INFO in app.py - framework_error [line:17]: 400 Bad Request: {'host': ['不许为空']}
[2019-10-11 22:14:40,058] INFO in app.py - framework_error [line:17]: HTTPConnectionPool(host='www.guojiaxing.redw', port=2375): Max retries exceeded with url: /v1.35/info (Caused by NewConnectionError('<urllib3.connection.HTTPConnection object at 0x0000015539A7A630>: Failed to establish a new connection: [Errno 11001] getaddrinfo failed',))
[2019-10-11 22:29:43,085] INFO in app.py - framework_error [line:17]: append() takes exactly one argument (2 given)
[2019-10-11 22:34:09,571] INFO in app.py - framework_error [line:17]: 400 Bad Request: {'host': ['不许为空']}
[2019-10-11 22:35:34,150] INFO in app.py - framework_error [line:17]: 400 Bad Request: {'host': ['不许为空']}
[2019-10-11 22:35:37,614] INFO in app.py - framework_error [line:17]: 400 Bad Request: {'host': ['不许为空']}
[2019-10-11 22:36:03,747] INFO in app.py - framework_error [line:17]: 400 Bad Request: {'host': ['不许为空']}
[2019-10-11 22:36:07,762] INFO in app.py - framework_error [line:17]: 400 Bad Request: {'host': ['不许为空']}
[2019-10-11 22:58:24,630] INFO in app.py - framework_error [line:17]: 400 Bad Request: {'host': ['不许为空']}
[2019-10-12 09:29:14,569] INFO in app.py - framework_error [line:17]: 400 Bad Request: {'host': ['不许为空']}
[2019-10-12 09:56:44,484] INFO in app.py - framework_error [line:17]: 400 Bad Request: {'host': ['不许为空']}
[2019-10-12 09:56:52,197] INFO in app.py - framework_error [line:17]: 400 Bad Request: {'host': ['不许为空']}
[2019-10-12 10:12:35,291] INFO in app.py - framework_error [line:17]: 400 Bad Request: {'host': ['不许为空']}
[2019-10-12 10:12:41,739] INFO in app.py - framework_error [line:17]: 400 Bad Request: {'host': ['不许为空']}
[2019-10-12 10:15:02,138] INFO in app.py - framework_error [line:17]: 400 Bad Request: {'host': ['不许为空']}
[2019-10-12 10:15:15,847] INFO in app.py - framework_error [line:17]: 400 Bad Request: {'host': ['不许为空']}
[2019-10-12 10:18:06,627] INFO in app.py - framework_error [line:17]: 400 Bad Request: {'host': ['不许为空']}
[2019-10-12 10:18:12,222] INFO in app.py - framework_error [line:17]: 400 Bad Request: {'host': ['不许为空']}
[2019-10-12 11:17:28,342] INFO in app.py - framework_error [line:17]: 400 Bad Request: {'host': ['不许为空']}
[2019-10-12 11:17:39,635] INFO in app.py - framework_error [line:17]: 400 Bad Request: {'host': ['不许为空']}
[2019-10-12 13:36:38,969] INFO in app.py - framework_error [line:17]: 400 Bad Request: {'host': ['不许为空']}
[2019-10-12 13:36:44,266] INFO in app.py - framework_error [line:17]: 400 Bad Request: {'host': ['不许为空']}
[2019-10-12 13:38:36,987] INFO in app.py - framework_error [line:17]: 400 Bad Request: {'host': ['不许为空']}
[2019-10-12 13:38:39,517] INFO in app.py - framework_error [line:17]: 400 Bad Request: {'host': ['不许为空']}
[2019-10-12 13:38:52,979] INFO in app.py - framework_error [line:17]: 400 Bad Request: {'host': ['不许为空']}
[2019-10-12 13:48:05,688] INFO in app.py - framework_error [line:17]: 400 Bad Request: {'host': ['不许为空']}
[2019-10-12 13:48:10,502] INFO in app.py - framework_error [line:17]: 400 Bad Request: {'host': ['不许为空']}
[2019-10-12 15:52:10,752] INFO in app.py - framework_error [line:17]: 404 Not Found: The requested URL was not found on the server.  If you entered the URL manually please check your spelling and try again.
[2019-10-12 15:53:16,766] INFO in app.py - framework_error [line:17]: 404 Not Found: The requested URL was not found on the server.  If you entered the URL manually please check your spelling and try again.
[2019-10-12 15:57:36,722] INFO in app.py - framework_error [line:17]: HTTPConnectionPool(host='www.guojiaxing.redw', port=2375): Max retries exceeded with url: /v1.35/info (Caused by NewConnectionError('<urllib3.connection.HTTPConnection object at 0x000001F7CA02A048>: Failed to establish a new connection: [Errno 11001] getaddrinfo failed',))
[2019-10-12 15:59:30,237] INFO in app.py - framework_error [line:17]: 404 Not Found: The requested URL was not found on the server.  If you entered the URL manually please check your spelling and try again.
[2019-10-13 11:35:53,570] INFO in app.py - framework_error [line:17]: 'str' object has no attribute 'splite'
[2019-10-13 11:50:41,608] INFO in app.py - framework_error [line:17]: unsupported operand type(s) for +: 'int' and 'str'
[2019-10-13 14:50:26,472] INFO in app.py - framework_error [line:17]: 'ClientForm' object has no attribute 'page'
[2019-10-13 14:51:57,459] INFO in app.py - framework_error [line:17]: unsupported operand type(s) for -: 'str' and 'int'
[2019-10-13 14:53:52,477] INFO in app.py - framework_error [line:17]: 'list' object has no attribute 'length'
[2019-10-13 14:54:16,481] INFO in app.py - framework_error [line:17]: 'list' object has no attribute 'len'
[2019-10-13 18:35:13,574] INFO in app.py - framework_error [line:17]: HTTPConnectionPool(host='127.0.0.1', port=2375): Max retries exceeded with url: /v1.35/images/json?only_ids=0&all=0 (Caused by NewConnectionError('<urllib3.connection.HTTPConnection object at 0x0000027DE30F6BE0>: Failed to establish a new connection: [WinError 10061] 由于目标计算机积极拒绝，无法连接。',))
[2019-10-13 19:16:51,935] INFO in app.py - framework_error [line:17]: 'ClientForm' object has no attribute 'image'
[2019-10-13 19:56:37,348] INFO in app.py - framework_error [line:17]: 404 Client Error: Not Found ("No such image: harbor.guojiaxing.red/public/travel:v1")
[2019-10-13 20:00:15,390] INFO in app.py - framework_error [line:17]: 404 Client Error: Not Found ("No such image: mysql5.7:latest")
[2019-10-13 20:00:26,352] INFO in app.py - framework_error [line:17]: 409 Client Error: Conflict ("conflict: unable to remove repository reference "mysql:5.7" (must force) - container 2bd08d15a483 is using its referenced image a1aa4f76fab9")
[2019-10-13 21:14:15,326] INFO in app.py - framework_error [line:17]: 409 Client Error: Conflict ("conflict: unable to remove repository reference "mysql:5.7" (must force) - container 1b26f28695d3 is using its referenced image a1aa4f76fab9")
[2019-10-13 21:20:01,556] INFO in app.py - framework_error [line:17]: 404 Client Error: Not Found ("No such image: mysql:5.71")
[2019-10-13 21:26:44,403] INFO in app.py - framework_error [line:17]: type object 'APIError' has no attribute 'response'
[2019-10-13 21:30:54,361] INFO in app.py - framework_error [line:17]: __str__() missing 1 required positional argument: 'self'
[2019-10-13 21:33:16,316] INFO in app.py - framework_error [line:17]: 404 Client Error: Not Found ("No such image: mysql:5.71")
[2019-10-13 21:33:37,314] INFO in app.py - framework_error [line:17]: 409 Client Error: Conflict ("conflict: unable to remove repository reference "mysql:5.7" (must force) - container 1b26f28695d3 is using its referenced image a1aa4f76fab9")
[2019-10-13 22:36:39,297] INFO in app.py - framework_error [line:17]: HTTPConnectionPool(host='www.guojiaxing.red', port=2375): Read timed out. (read timeout=60)
[2019-10-14 19:37:43,631] INFO in app.py - framework_error [line:17]: 500 Internal Server Error: None
[2019-10-14 19:41:24,199] INFO in app.py - framework_error [line:17]: 500 Server Error: Internal Server Error ("Get https://harbor.guojiaxing.red/v2/: dial tcp 47.111.114.175:443: connect: connection refused")
[2019-10-14 19:52:57,547] INFO in app.py - framework_error [line:17]: 'dict' object has no attribute 'Name'
[2019-10-14 21:38:53,933] INFO in app.py - framework_error [line:17]: __init__() missing 1 required positional argument: 'form_class'
[2019-10-14 21:41:18,064] INFO in app.py - framework_error [line:17]: run() got an unexpected keyword argument 'link'
[2019-10-14 21:43:16,385] INFO in app.py - framework_error [line:17]: __init__() missing 1 required positional argument: 'form_class'
[2019-10-14 21:44:23,002] INFO in app.py - framework_error [line:17]: 'dict' object has no attribute 'validate'
[2019-10-14 21:45:00,074] INFO in app.py - framework_error [line:17]: 'UnboundField' object has no attribute 'validate'
[2019-10-14 21:45:15,521] INFO in app.py - framework_error [line:17]: 'UnboundField' object is not callable
[2019-10-14 21:46:06,944] INFO in app.py - framework_error [line:17]: str() takes at most 3 arguments (4 given)
[2019-10-14 21:49:28,268] INFO in app.py - framework_error [line:17]: the JSON object must be str, bytes or bytearray, not 'dict'
[2019-10-14 21:50:44,110] INFO in app.py - framework_error [line:17]: Expecting property name enclosed in double quotes: line 1 column 2 (char 1)
[2019-10-14 21:56:38,963] INFO in app.py - framework_error [line:17]: Expecting property name enclosed in double quotes: line 1 column 2 (char 1)
[2019-10-14 22:01:04,638] INFO in app.py - framework_error [line:17]: __init__() got an unexpected keyword argument 'formdata'
[2019-10-14 22:03:20,471] INFO in app.py - framework_error [line:17]: run() got an unexpected keyword argument 'link'
[2019-10-14 22:05:26,694] INFO in app.py - framework_error [line:17]: name 'link' is not defined
[2019-10-15 09:32:56,477] INFO in app.py - framework_error [line:17]: local variable 'ports' referenced before assignment
[2019-10-15 09:35:20,683] INFO in app.py - framework_error [line:17]: local variable 'ports' referenced before assignment
[2019-10-15 09:35:47,423] INFO in app.py - framework_error [line:17]: local variable 'ports1' referenced before assignment
[2019-10-15 09:54:44,042] INFO in app.py - framework_error [line:17]: 500 Server Error: Internal Server Error ("Cannot link to /mysql_master, as it does not belong to the default network")
[2019-10-15 09:56:43,918] INFO in app.py - framework_error [line:17]: 409 Client Error: Conflict ("Conflict. The container name "/tal" is already in use by container "ed4276c81f16f15c94f905ca222e0b0d095c0b9d5496ae671beb09a5fa728ebd". You have to remove (or rename) that container to be able to reuse that name.")
[2019-10-15 13:32:38,589] INFO in app.py - framework_error [line:17]: 'StringField' object has no attribute 'restart'
[2019-10-15 13:33:06,964] INFO in app.py - framework_error [line:17]: 400 Client Error: Bad Request ("maximum retry count cannot be used with restart policy 'always'")
[2019-10-15 14:40:15,804] INFO in app.py - framework_error [line:17]: 'str' object has no attribute 'items'
[2019-10-15 17:29:29,697] INFO in app.py - framework_error [line:17]: 405 Method Not Allowed: The method is not allowed for the requested URL.
[2019-10-15 21:19:38,513] INFO in app.py - framework_error [line:17]: HTTPConnectionPool(host='127.0.0.1', port=2375): Max retries exceeded with url: /v1.35/images/json?only_ids=0&all=0 (Caused by NewConnectionError('<urllib3.connection.HTTPConnection object at 0x000001EA61876128>: Failed to establish a new connection: [WinError 10061] 由于目标计算机积极拒绝，无法连接。',))
[2019-10-15 21:19:40,798] INFO in app.py - framework_error [line:17]: HTTPConnectionPool(host='127.0.0.1', port=2375): Max retries exceeded with url: /v1.35/images/json?only_ids=0&all=0 (Caused by NewConnectionError('<urllib3.connection.HTTPConnection object at 0x000001EA62A7D860>: Failed to establish a new connection: [WinError 10061] 由于目标计算机积极拒绝，无法连接。',))
[2019-10-15 21:19:49,104] INFO in app.py - framework_error [line:17]: HTTPConnectionPool(host='127.0.0.1', port=2375): Max retries exceeded with url: /v1.35/images/json?only_ids=0&all=0 (Caused by NewConnectionError('<urllib3.connection.HTTPConnection object at 0x000001EA63A1E780>: Failed to establish a new connection: [WinError 10061] 由于目标计算机积极拒绝，无法连接。',))
